<robot name="cabinet_shelf">

  <material name="Wood">
    <color rgba="0.827 0.675 0.463 1.0"/>
  </material>
  <material name="LightWood">
    <color rgba="0.992, 0.871, 0.682, 1.0"/>
  </material>
  <material name="Metal">
    <color rgba="0.718, 0.753, 0.749, 1.0"/>
  </material>

  <link name="cabinet_bottom_plate">
    <inertial>
      <mass value="20.0" />
      <origin xyz="0 0 -1.0" /> 
      <inertia  ixx="2" ixy="0.0"  ixz="0.0"  iyy="2"  iyz="0.0"  izz="2" />
    </inertial>
    <visual>
      <origin xyz="0 0 0.01" rpy="0 0 0" />
      <geometry>
        <box size="0.35 0.45 0.02"/>
      </geometry>
      <material name="Wood"/>
    </visual>
    <collision>
      <origin xyz="0 0 0.01" rpy="0 0 0" />
      <geometry>
        <box size="0.35 0.45 0.02"/>
      </geometry>
    </collision>
  </link>

  <link name="cabinet_middle_plate1">
    <inertial>
      <mass value="1.0" />
      <origin xyz="0 0 0.0" />
      <inertia  ixx="0.01" ixy="0.0"  ixz="0.0"  iyy="0.01"  iyz="0.0"  izz="0.01" />
    </inertial>
    <visual>
      <origin xyz="0 0 0.76" rpy="0 0 0" />
      <geometry>
        <box size="0.35 0.45 0.02"/>
      </geometry>
      <material name="Wood"/>
    </visual>
    <collision>
      <origin xyz="0 0 0.76" rpy="0 0 0" />
      <geometry>
        <box size="0.35 0.45 0.02"/>
      </geometry>
    </collision>
  </link>
  <link name="cabinet_middle_plate2">
    <inertial>
      <mass value="1.0" />
      <origin xyz="0 0 0.0" /> 
      <inertia  ixx="0.01" ixy="0.0"  ixz="0.0"  iyy="0.01"  iyz="0.0"  izz="0.01" />
    </inertial>
    <visual>
      <origin xyz="0 0 0.51" rpy="0 0 0" />
      <geometry>
        <box size="0.35 0.45 0.02"/>
      </geometry>
      <material name="Wood"/>
    </visual>
    <collision>
      <origin xyz="0 0 0.51" rpy="0 0 0" />
      <geometry>
        <box size="0.35 0.45 0.02"/>
      </geometry>
    </collision>
  </link>
  <link name="cabinet_top_plate">
    <inertial>
      <mass value="1.0" />
      <origin xyz="0 0 0.0" /> 
      <inertia  ixx="0.01" ixy="0.0"  ixz="0.0"  iyy="0.01"  iyz="0.0"  izz="0.01" />
    </inertial>
    <visual>
      <origin xyz="0 0 1.01" rpy="0 0 0" />
      <geometry>
        <box size="0.35 0.45 0.02"/>
      </geometry>
      <material name="Wood"/>
    </visual>
    <collision>
      <origin xyz="0 0 1.01" rpy="0 0 0" />
      <geometry>
        <box size="0.35 0.45 0.02"/>
      </geometry>
    </collision>
  </link>
  <link name="cabinet_left_plate">
    <inertial>
      <mass value="1.0" />
      <origin xyz="0 0 0.0" /> 
      <inertia  ixx="0.01" ixy="0.0"  ixz="0.0"  iyy="0.01"  iyz="0.0"  izz="0.01" />
    </inertial>
    <visual>
      <origin xyz="0 -0.235 0.51" rpy="0 0 0" />
      <geometry>
        <box size="0.35 0.02 1.02"/>
      </geometry>
      <material name="Wood"/>
    </visual>
    <collision>
      <origin xyz="0 -0.235 0.51" rpy="0 0 0" />
      <geometry>
        <box size="0.35 0.02 1.02"/>
      </geometry>
    </collision>
  </link>
  <link name="cabinet_right_plate">
    <inertial>
      <mass value="1.0" />
      <origin xyz="0 0 0.0" /> 
      <inertia  ixx="0.01" ixy="0.0"  ixz="0.0"  iyy="0.01"  iyz="0.0"  izz="0.01" />
    </inertial>
    <visual>
      <origin xyz="0 0.235 0.51" rpy="0 0 0" />
      <geometry>
        <box size="0.35 0.02 1.02"/>
      </geometry>
      <material name="Wood"/>
    </visual>
    <collision>
      <origin xyz="0 0.235 0.51" rpy="0 0 0" />
      <geometry>
        <box size="0.35 0.02 1.02"/>
      </geometry>
    </collision>
  </link>
  <link name="cabinet_back_plate">
    <inertial>
      <mass value="1.0" />
      <origin xyz="0 0 -5" /> 
      <inertia  ixx="0.01" ixy="0.0"  ixz="0.0"  iyy="0.01"  iyz="0.0"  izz="0.01" />
    </inertial>
    <visual>
      <origin xyz="-0.185 0 0.51" rpy="0 0 0" />
      <geometry>
        <box size="0.02 0.45 1.02"/>
      </geometry>
      <material name="Wood"/>
    </visual>
    <collision>
      <origin xyz="-0.21 0 0.51" rpy="0 0 0" />
      <geometry>
        <box size="0.02 0.45 1.02"/>
      </geometry>
    </collision>
  </link>

  <link name="cabinet_door_plate">
    <inertial>
      <mass value="1.0" />
      <origin xyz="0 0 0.0" />
      <inertia  ixx="0.01" ixy="0.0"  ixz="0.0"  iyy="0.01"  iyz="0.0"  izz="0.01" />
    </inertial>
    <visual>
      <origin xyz="0.01 0.245 0.25" rpy="0 0 0" />
      <geometry>
        <box size="0.02 0.48 0.51"/>
      </geometry>
      <material name="Wood"/>
    </visual>
    <collision>
      <origin xyz="0.235 0 0.26" rpy="0 0 0" />
      <geometry>
        <box size="0.02 0.49 0.51"/>
      </geometry>
    </collision>
  </link>
  <link name="cabinet_door_handle">
    <inertial>
      <mass value="0.1" />
      <origin xyz="0 0 0.0" />
      <inertia  ixx="0.01" ixy="0.0"  ixz="0.0"  iyy="0.01"  iyz="0.0"  izz="0.01" />
    </inertial>
    <visual>
      <origin xyz="0.03 0.4 0.25" rpy="0 0 0" />
      <geometry>
        <cylinder radius="0.01" length="0.15"/>
      </geometry>
      <material name="Metal"/>
    </visual>
    <collision>
      <origin xyz="0.03 0.4 0.25" rpy="0 0 0" />
      <geometry>
        <cylinder radius="0.01" length="0.15"/>
      </geometry>
    </collision>
  </link>


  <joint name="middle_plate1" type="fixed">
    <parent link="cabinet_bottom_plate"/>
    <child link="cabinet_middle_plate1"/>
    <origin xyz="0 0 0"/>
  </joint>
  <joint name="middle_plate2" type="fixed">
    <parent link="cabinet_bottom_plate"/>
    <child link="cabinet_middle_plate2"/>
    <origin xyz="0 0 0"/>
  </joint>

  <joint name="top_plate" type="fixed">
    <parent link="cabinet_bottom_plate"/>
    <child link="cabinet_top_plate"/>
    <origin xyz="0 0 0"/>
  </joint>
  <joint name="left_plate" type="fixed">
    <parent link="cabinet_bottom_plate"/>
    <child link="cabinet_left_plate"/>
    <origin xyz="0 0 0"/>
  </joint>
  <joint name="right_plate" type="fixed">
    <parent link="cabinet_bottom_plate"/>
    <child link="cabinet_right_plate"/>
    <origin xyz="0 0 0"/>
  </joint>
  <joint name="back_plate" type="fixed">
    <parent link="cabinet_bottom_plate"/>
    <child link="cabinet_back_plate"/>
    <origin xyz="0 0 0"/>
  </joint>

  <joint name="cabinet_door_hinge" type="revolute">
    <parent link="cabinet_bottom_plate"/>
    <child link="cabinet_door_plate"/>
    <origin rpy="0 0 0" xyz="0.180 -0.237 0"/>
    <axis xyz="0 0 1"/>
    <limit upper="0" lower="-1.6" velocity="100" effort="100"/>
  </joint>

  <joint name="cabinet_door_handle" type="fixed">
    <parent link="cabinet_door_plate"/>
    <child link="cabinet_door_handle"/>
    <origin xyz="0 0 0"/>
  </joint>




  <gazebo reference="cabinet_bottom_plate">
    <mu1>100.0</mu1>
    <mu2>100.0</mu2>
  </gazebo>
  <gazebo>
    <static>true</static>
  </gazebo>
</robot>
